Workbook

Sheet Abilities
A1: =COUNTIF(A2:A1999,"=0") -> 458 | E1: This column is for developing the actual game text of an ability
B2: Category | C2: Ability Name | D2: Ability Description | E2: Rules Text | F2: BP Cost | G2: Affinity req | H2: W | I2: U | J2: B | K2: R | L2: G | M2: tot | O2: R1 | P2: R2 | Q2: R3 | R2: R4 | S2: R5 | T2: R6 | U2: R7 | V2: R8 | W2: R9 | X2: R10
A3: =ISBLANK(B3)+ISBLANK(C3)+ISBLANK(D3)+ISBLANK(E3)+ISBLANK(F3)+ISBLANK(G3) -> 0 | B3: Aura | C3: Drinker of Souls | D3: Automatically absorb energy from dying / recently slain foes | E3: A creature that begins dying or loses health while dying within the aura rolls BOD vs. WIL to resist, failure or tie results in its death. This aura automatically succeeds against a target that has been dead for up to 5 rounds, on 6+ rounds no effect. When a creature's soul is consumed gain 1 temporary HP, stacking. A creature's soul can only be so consumed once. If multiple instances of this ability would trigger on a soul, the owner who most recently acted in initiative gets priority, then second most recent, etc. | F3: 10 | G3: 7B,(9) | H3: 0 | I3: 0 | J3: 6 | K3: 0 | L3: 0 | M3: 6 | O3: 10 | Y3: Drinker of souls generates stacking temp health and provides a culling effect. The value of the culling effect remains to be seen as enemies healing downed allies seems a lot rarer than it should be? Stackable THP feels like something for the middle bracket (TR 4-6, maybe 7). How does it piggyback on other THP generation? Given it takes up the aura slot, this ability can likely preserve its low cost. Though it should probably be limited at the very least +20 Generates 1 THP -10 On kill trigger (any ally or you), no action +40? stacking THP -20 aura discount new price: 30
A4: =ISBLANK(B4)+ISBLANK(C4)+ISBLANK(D4)+ISBLANK(E4)+ISBLANK(F4)+ISBLANK(G4) -> 0 | B4: Aura | C4: Enduring Presence | D4: Damage dampening, discharge to mitigate one hit | E4: Allies within the aura gain RANK+1 damage dampening. Discharge: one subject of the aura gets RANK+1+(quantity of subjects) damage dampening against one attack. | F4: 60/70/80 | G4: 12W,(15) 16W,(21) 20W,(27) | H4: 6 | M4: 6 | O4: 60 | P4: 130 | Q4: 210 | Y4: Big white defensive aura. Doesn't feel out of place on any details at this point 200/300/400 provides Rank+1 dampening 2x Provides benefits to party -20 aura discount discharge function 0.2x Complex, prepared in advance 500/600/700 dampening
A5: =ISBLANK(B5)+ISBLANK(C5)+ISBLANK(D5)+ISBLANK(E5)+ISBLANK(F5)+ISBLANK(G5) -> 0 | B5: Aura | C5: Fear Aura | D5: This fear aura triggers on any aggressive action. | E5: You may attempt a free intimidation check against all enemies within the aura once per round as part of an attack. The effects of the intimidation check apply after the attack is resolved. As normal, you can only apply one fear effect to a given target once per turn. | F5: 15 | G5: 4R,5(B|R),(12) | H5: 0 | I5: 0 | J5: 6 | K5: 6 | L5: 0 | M5: 6 | O5: 15 | Y5: Fear is supposedly a B|R effect. So perhaps exclusive B|R? TR4-6. Price can stay low given it triggers infrequently. It's otherwise a potent effect, but it is an aura.
A6: =ISBLANK(B6)+ISBLANK(C6)+ISBLANK(D6)+ISBLANK(E6)+ISBLANK(F6)+ISBLANK(G6) -> 0 | B6: Aura | C6: Feedback Aura | D6: Nearby enemies subject to damage when you are wounded | E6: Enemies in the aura (CHA/2 *5 ft instead of standard CHA*5) resist (damage you took+CHA-2) as psychic damage with mental soak. | F6: 10 | G6: 4(W|B),4(W|U|B),(15) | H6: 0 | I6: 4 | J6: 4 | K6: 0 | L6: 0 | M6: 8 | O6: 10 | Y6: Defense bypassing thorns effect. Feels to be more of a W|B effect. Good for popping mooks. Has obvious synergy with THP
A7: =ISBLANK(B7)+ISBLANK(C7)+ISBLANK(D7)+ISBLANK(E7)+ISBLANK(F7)+ISBLANK(G7) -> 0 | B7: Aura | C7: Generous Enchancements | D7: Share the effects of one ongoing buff you are subject to with all allies in range of this aura. | E7: When you trigger a buff you may designate it as being Generously Enhanced. This ability becomes the shared aura effect of Generous Enhancements and does not count for you as a body buff if it was one. As a Extra action you may designate a buff currently on you to become Generously Enhanced, it becomes the aura effect and any current aura effect reverts to its normal buff state. | F7: 100 | G7: 12W,12G,(30) | O7: 100
A8: =ISBLANK(B8)+ISBLANK(C8)+ISBLANK(D8)+ISBLANK(E8)+ISBLANK(F8)+ISBLANK(G8) -> 0 | B8: Aura | C8: Glare of the noonday sun | D8: nonlethal damage vs. everything at start of your turn | E8: All creatures within (CHA/2 + RANK) ft (including you) must soak (BOD + 2* RANK) fire damage at the start of your turn. This damage is always nonlethal. | F8: 30/40/50 | G8: 14(W|R|G),(18) 16(W|R|G),(21) 19(W|R|G),(24) | H8: 12 | K8: 12 | L8: 12 | M8: 12 | O8: 30 | P8: 70 | Q8: 120 | Y8: tri color exclusive, accessible to 3x 2c, matching 3c, and 6 (2/3) match 3c that stretch. Culls mooks generally
A9: =ISBLANK(B9)+ISBLANK(C9)+ISBLANK(D9)+ISBLANK(E9)+ISBLANK(F9)+ISBLANK(G9) -> 0 | B9: Aura | C9: Lawbringer's Presence | D9: Free counterspell attempts on any spells cast within this aura | E9: You may attempt to counterspell any spell cast within this aura for (0) | F9: 100 | G9: 8W,8U,8(W|U),(30) | O9: 100 | Y9: Should all capstones be partial color flex?
A10: =ISBLANK(B10)+ISBLANK(C10)+ISBLANK(D10)+ISBLANK(E10)+ISBLANK(F10)+ISBLANK(G10) -> 0 | B10: Aura | C10: Magic Circle of Heart | D10: All allies in the aura gain rank X to an element of your choice, chosen on activation. | E10: All allies in the aura gain 2*RANK resist to ELEMENT of your choice, chosen on activation. | F10: 20,30,40 | G10: 3W,(9) per | O10: 20 | P10: 50 | Q10: 90 | Y10: May be a bit underpriced for how potent it could be? Green magic resist seems to be another theme that could be called upon
A11: =ISBLANK(B11)+ISBLANK(C11)+ISBLANK(D11)+ISBLANK(E11)+ISBLANK(F11)+ISBLANK(G11) -> 0 | B11: Aura | C11: Mana Leech | D11: Name a color. All drain using abilities except for the named color are subject to 1 higher drain. Whenever such an ability is used, roll 4 dice and heal HITS drain. | E11: Name a color on aura activation. All spells and other drain using abilities used within the aura except for the named color may take 2+2*RANK overload. If they don't, roll 2+2*rank dice and heal HITS drain and the ability user loses HITS drain. | F11: 20,30,40 | G11: 7U,7B,(18) 9U,9B,(24) 12U,12B,(30) | H11: 10 | J11: 10 | M11: 10 | O11: 20 | P11: 50 | Q11: 90 | Y11: Spells only. May be slighly underpriced?
A12: =ISBLANK(B12)+ISBLANK(C12)+ISBLANK(D12)+ISBLANK(E12)+ISBLANK(F12)+ISBLANK(G12) -> 0 | B12: Aura | C12: Menacing Presence | D12: Penalty to enemies trying to attack allies other than you | E12: Enemies within (CHA*5 feet) take (CHA) penalty to their attack pools if targeting anything but a user of Menacing Presence. If enemies are not aware of you, this aura does not affect them. | F12: 10 | G12: 4W,5(W|B|G),(12) | H12: 6 | I12: 0 | J12: 6 | K12: 0 | L12: 0 | M12: 6 | O12: 10
A13: =ISBLANK(B13)+ISBLANK(C13)+ISBLANK(D13)+ISBLANK(E13)+ISBLANK(F13)+ISBLANK(G13) -> 0 | B13: Aura | C13: Natural Shielding | D13: Aura, allies gain resistances | E13: All allies within the aura gain +RANK armor, and 2*RANK+2 dice on rolls to resist effects originating from other recipients of this aura. | F13: 40/50/60 | G13: 7G,(15) 10G,(21) 13G,(27) | L13: 4 | M13: 10 | O13: 40 | P13: 90 | Q13: 150
A14: =ISBLANK(B14)+ISBLANK(C14)+ISBLANK(D14)+ISBLANK(E14)+ISBLANK(F14)+ISBLANK(G14) -> 0 | B14: Aura | C14: Never surrender | D14: grants diehard to allies | E14: Allies do not fall unconscious when a damage track is filled. They still die from overflow. | F14: 10 | G14: 6W,6R,(15) | H14: 8 | I14: 0 | J14: 0 | K14: 8 | L14: 0 | M14: 8 | O14: 10
A15: =ISBLANK(B15)+ISBLANK(C15)+ISBLANK(D15)+ISBLANK(E15)+ISBLANK(F15)+ISBLANK(G15) -> 0 | B15: Aura | C15: No Retreat! | D15: Your inspiration prevents enemies from being able to withdraw safely | E15: Enemies within your zone of control provoke attacks of opportunity from you when using any form of movement even if they would not normally provoke. At rank 2 all enemies within CHA*5 always provoke attacks of opportunity (from threatening allies) when moving through an allies zone of control. All forms of movement, including instant teleportation, provoke. Allies must also be within this aura to gain these benefits. | F15: 20/20 | G15: 4W,5(W|B),(12) 7W,9(W|B),(21) | H15: 6 | J15: 6 | M15: 6 | O15: 20 | P15: 40
A16: =ISBLANK(B16)+ISBLANK(C16)+ISBLANK(D16)+ISBLANK(E16)+ISBLANK(F16)+ISBLANK(G16) -> 0 | B16: Aura | C16: Rally Morale | D16: Your allies may use your willpower in place of their own, or their willpower + RANK (whichever is higher) when resisting most effects. This does not apply to drain checks. | E16: Your allies may use your willpower in place of their own, or their willpower + RANK (whichever is higher) when resisting most effects. This does not apply to drain checks. | F16: 10 | G16: 6W,6(W|U|G),(15) | H16: 6 | I16: 0 | J16: 0 | K16: 0 | L16: 0 | M16: 6 | O16: 10 | P16: 20 | Q16: 30
A17: =ISBLANK(B17)+ISBLANK(C17)+ISBLANK(D17)+ISBLANK(E17)+ISBLANK(F17)+ISBLANK(G17) -> 0 | B17: Aura | C17: Rallying Aura | D17: bonus vs. fear and charm, bonus on combat | E17: Resist fear, resist charm, combat; +1 die per rank | F17: 15 30 45 | G17: 3W,4(W|R),(9) 7W,7(W|R),(18) 10W,11(W|R),(27) | H17: 3 | I17: 0 | J17: 0 | K17: 3 | L17: 0 | M17: 6 | O17: 15 | P17: 45 | Q17: 90
A18: =ISBLANK(B18)+ISBLANK(C18)+ISBLANK(D18)+ISBLANK(E18)+ISBLANK(F18)+ISBLANK(G18) -> 0 | B18: Aura | C18: Rallying Spirit | D18: Your combat prowess brings inspiration to your allies, their morale confers healing | E18: When you make a successful melee attack you may heal an ally within CHA*5 ft RANK*4 meat or RANK*8 stam health. (This healing is subject to normal healing rules.) | F18: 10 | G18: 6W,(12) 9W,(18) 12W,(24) 18W,(30) | H18: 8 | M18: 8 | O18: 10 | P18: 20 | Q18: 30 | R18: 40
A19: =ISBLANK(B19)+ISBLANK(C19)+ISBLANK(D19)+ISBLANK(E19)+ISBLANK(F19)+ISBLANK(G19) -> 0 | B19: Aura | C19: Repositioning Aura | D19: When you hit with an attack you may designate an ally within your aura to take a move action. | E19: When you hit with an attack you may designate an ally within your aura to move up to their movement rate. | F19: 20 | G19: 3W,(15) | O19: 20
A20: =ISBLANK(B20)+ISBLANK(C20)+ISBLANK(D20)+ISBLANK(E20)+ISBLANK(F20)+ISBLANK(G20) -> 0 | B20: Aura | C20: Shielding Aura | D20: When you make a parry, all allies within the aura gain 1 temp hp | E20: When you succesfully block or parry, all allies except you within the aura gain 2 temp hp | F20: 40 | G20: 7W,(21) | O20: 40
A21: =ISBLANK(B21)+ISBLANK(C21)+ISBLANK(D21)+ISBLANK(E21)+ISBLANK(F21)+ISBLANK(G21) -> 0 | B21: Aura | C21: Skill Teamwork | D21: Boost allies' skills for skills you have high ranks in (DEPRECATED) | E21: DEPRECATED Rank 1: up to 2 Rank 2: up to 4 Rank 3: up to 6 Rank 4: up to 8 | F21: 20,40,60,80 | G21: 1W,1G,1(W|G),(6) per | H21: 4 | I21: 4 | J21: 0 | K21: 0 | L21: 4 | M21: 4 | O21: 20 | P21: 60 | Q21: 120 | R21: 200
A22: =ISBLANK(B22)+ISBLANK(C22)+ISBLANK(D22)+ISBLANK(E22)+ISBLANK(F22)+ISBLANK(G22) -> 0 | B22: Aura | C22: Slow Aura | D22: increase initiative cost of enemy actions | E22: Enemy's actions cost 1+(RANK) more initiative so long as they are within (5*CHA feet) of you. If another effect would inflict a penalty on the initiative cost of actions only the highest penalty applies. | F22: 10 15 20 | G22: 3U,4(W|U),(9) 7U,7(W|U),(18) 10U,11(W|U),(27) | H22: 6 | I22: 6 | J22: 6 | K22: 0 | L22: 0 | M22: 6 | O22: 10 | P22: 25 | Q22: 45
A23: =ISBLANK(B23)+ISBLANK(C23)+ISBLANK(D23)+ISBLANK(E23)+ISBLANK(F23)+ISBLANK(G23) -> 0 | B23: Aura | C23: Warleader | D23: Allies can attack right after you with a bonus. | E23: The first time you attack each turn all allies within range may take their turn immediately after yours. An ally who chooses to do so may only move or make attacks during that turn. Allies who make use of this ability gain a stacking, refreshing +1 dice to all attack, block, parry rolls until the end of their next turn. The maximum benefit of this bonus is your CHA. | F23: 50 | G23: 9W,9R,(24) | O23: 50
A24: =ISBLANK(B24)+ISBLANK(C24)+ISBLANK(D24)+ISBLANK(E24)+ISBLANK(F24)+ISBLANK(G24) -> 0 | B24: Buff | C24: All outta Bubblegum | D24: various grapple, melee roughness bonuses | E24: Body Buff RANK-1 damage dampening ignore RANK points of wound penalty +RANK vs. knockdown, disarm, trip, resisting grapple Melee attacks trigger knockdown on hit. Target rolls physical resist or gymnastics vs. unsoaked damage. Enemies that fail to escape your grapples take damage as if you made the grapple attack action against them Ignore half an enemy's armor with your grapple attacks | F24: 20/30/40 | G24: 4(R|G),(9) 9(R|G),(18) 13(R|G),(27) | K24: 3 | L24: 3 | M24: 6 | O24: 20 | P24: 50 | Q24: 90
A25: =ISBLANK(B25)+ISBLANK(C25)+ISBLANK(D25)+ISBLANK(E25)+ISBLANK(F25)+ISBLANK(G25) -> 0 | B25: Buff | C25: Arcane Conduit | D25: Casting spells | E25: Body Buff Casting a spell generates a mana charge. Charges may be expended as follows 2-Spent to mitigate an overload (per 1) 2-Spent in place of init costs on counterspelling/redirecting (per 5) 2-Spent to mitigate a counterspell/redirect attempt against one of your spells (-3 dice to opposed attempt per) Max charges = 2*RANK These charges decay after one minute of not generating nor using charges. If you would overflow your limit on charges take drain equal to the overflow amount. You shed sparking magical light (as a torch) while you have at least 2 charges. At Rank 2: Centering generates 1 charge, every point of drain you take from spellcasting generates 1 charge. At Rank 3: All charge generation is increased by +1 | F25: 30/40/80 | G25: 4U,4R,(18) 6U,6R,(24) 8U,8R,(30) | I25: 7 | K25: 7 | M25: 14 | O25: 30 | P25: 70 | Q25: 150
A26: =ISBLANK(B26)+ISBLANK(C26)+ISBLANK(D26)+ISBLANK(E26)+ISBLANK(F26)+ISBLANK(G26) -> 0 | B26: Buff | C26: Avatar of Malice | D26: Empower attacks, lifesteal, ignore full defense | E26: Body buff. All damage you deal is applied as Dark damage post mitigation. Enemies need to spend (5) in order for their total defense to apply against your attack. Whenever your melee attack deals damage to one or more targets gain 2 temp hp, your temp hp may stack. You treat all incoming dark damage and dark damage you suffer as normal damage. After damage is calculated against you, you may move up to (WIL/2) points of it to the delayed track. At the end of the round you lose health equal to the damage in the delayed track, the track then empties. | F26: 100 | G26: 24B,(30) | J26: 20 | M26: 20 | O26: 100
A27: =ISBLANK(B27)+ISBLANK(C27)+ISBLANK(D27)+ISBLANK(E27)+ISBLANK(F27)+ISBLANK(G27) -> 0 | B27: Buff | C27: Avatar of the Heart | D27: Let there be heals | E27: Body Buff When your healing effects heal a creature for at least 1 health you also grant them 2 temp hp. This temp HP can stack on existing temp hp. You may spend 1L in place of any drain you suffer as part of casting a healing effect, this also mitigates all drain for recipients of this healing effect. you may take 3 on all healing rolls You may trigger healing effects as an interrupt at (5) | F27: 100 | G27: 24W,(30) | H27: 20 | M27: 20 | O27: 100
A28: =ISBLANK(B28)+ISBLANK(C28)+ISBLANK(D28)+ISBLANK(E28)+ISBLANK(F28)+ISBLANK(G28) -> 0 | B28: Buff | C28: Bastion | D28: Defensive bonuses, reduced offensive power | E28: half Action. Increase damage dampening by RANK+2. Reduce the starting power of your attacks by RANK+2. This is a body buff | F28: 50 per | G28: 3W,(15) 5W,(21) 6W,(27) | H28: 6 | I28: 0 | J28: 0 | K28: 0 | L28: 0 | M28: 6 | O28: 50 | P28: 100 | Q28: 150
A29: =ISBLANK(B29)+ISBLANK(C29)+ISBLANK(D29)+ISBLANK(E29)+ISBLANK(F29)+ISBLANK(G29) -> 0 | B29: Buff | C29: Bonemonger | D29: Successful attacks generate a temp hp shield, can detonate temp hp shield | E29: Successful attacks generate 2 temp hp. You may detonate your temp hp, discharging the buff, as a full action to deal BOD+temp hp DV as a 10ft AoE attack (attacking with your weapon skill or spellcasting dicepool). This is a body buff. | F29: 40 | G29: 7W,7B,(18) | O29: 40
A30: =ISBLANK(B30)+ISBLANK(C30)+ISBLANK(D30)+ISBLANK(E30)+ISBLANK(F30)+ISBLANK(G30) -> 0 | B30: Buff | C30: Brambleward | D30: Ward against targeted magical effects, discharge for a burst of strength | E30: half action. Gain +3*RANK against targeted magical effects until the end of this round. You may discharge this effect to get +2 STR *RANK on one attempted action. | F30: 10,20,30 | G30: 4G,(9) 9G,(18) 13G,(27) | L30: 6 | M30: 6 | O30: 10 | P30: 30 | Q30: 60
A31: =ISBLANK(B31)+ISBLANK(C31)+ISBLANK(D31)+ISBLANK(E31)+ISBLANK(F31)+ISBLANK(G31) -> 0 | B31: Buff | C31: Charge Weapon | D31: Hold a spell in a weapon to be discharged upon striking | E31: You can cast spells into your weapon(s). The spells are discharged upon striking an opponent, one at a time, in the order they were cast in. -Spells that normally target dodge automatically hit with 0 net hits. In the case of AoE effects produced off this (RULING NEEDED) -Spells that target mental or physical resolve as normal. Casting a spell into a weapon is a half action. For every half action spent since the start of your last turn casting spells into your weapon(s) you may cast an additional spell as part of the half action. You may store up to (cast stat) spells at one time and you can only store spells of up to 1+(cast stat / 2) force. If the weapon leaves your possession for a minute all charges dissipate. Stored charges dissipate an hour after the last charge was added. | F31: 20 | G31: 3U,3R,(12) | I31: 6 | K31: 6 | M31: 6 | O31: 20
A32: =ISBLANK(B32)+ISBLANK(C32)+ISBLANK(D32)+ISBLANK(E32)+ISBLANK(F32)+ISBLANK(G32) -> 0 | B32: Buff | C32: Conjure weapon / armor | D32: Summon personalized weapon / armor, functions while in your keeping but phases out for others | E32: Binding weapons and/or armor is accomplished during one hour of downtime. You may summon any or all of the bound weapons/armor as if drawing (half), or dismiss them as if sheathing (half). When an item is dismissed it exists in a pocket dimension and access can be prevented by effects that limit extradimensional travel. Dismissed items count as attended. You may summon bound equipment back to you granted it has been at most one minute since you last made contact with it. If it is attended the attender must be willing. You are aware of the general direction your bound equipment is in if you become separated from it. You may bind one set of armor and (two one handed weapons or one two handed weapon) per rank. | F32: 5 per | G32: 1W,(6) | H32: 4 | M32: 4 | O32: 5 | P32: 10 | Q32: 15 | R32: 20 | S32: 25 | T32: 30 | U32: 35 | V32: 40 | W32: 45 | X32: 50
A33: =ISBLANK(B33)+ISBLANK(C33)+ISBLANK(D33)+ISBLANK(E33)+ISBLANK(F33)+ISBLANK(G33) -> 0 | B33: Buff | C33: Crisp and Cauterize | D33: Dealing direct fire damage procs a heal Healing procs a firebolt | E33: Body Buff. Whenever your attack or ability deals fire damage to a target you may heal an ally within 60ft for up to an equivalent amount of health. Whenever you heal an ally you may generate a single target ranged firebolt as per Elemental Blast, at DV-1 of default This ability cannot trigger itself | F33: 40 | G33: 9W,9R,(24) | O33: 40
A34: =ISBLANK(B34)+ISBLANK(C34)+ISBLANK(D34)+ISBLANK(E34)+ISBLANK(F34)+ISBLANK(G34) -> 0 | B34: Buff | C34: Deflecting Miasma | D34: More armor vs. ranged attacks, less armor vs. melee attack | E34: Gain RANK armor against ranged attacks, take a penalty of RANK armor against melee attacks. Activating this buff is a simple action. | F34: 10 | G34: ,(15) | O34: 10
A35: =ISBLANK(B35)+ISBLANK(C35)+ISBLANK(D35)+ISBLANK(E35)+ISBLANK(F35)+ISBLANK(G35) -> 0 | B35: Buff | C35: Displacer | D35: You occupy two adjacent squares, appearing to flicker between them. | E35: Body Buff Gain +3 on all defensive checks (not mental or physical resist) You occupy two adjacent squares. You may act from either position that you occupy. You may pass through thin obstacles at the cost of 5ft of movement. You can pay (5) init to solidify in one spot at any time, or a half action during your turn, stabilizing the effect until you spend a Extra action to resume it. | F35: 20 | G35: 3U,4(U|G),(15) | I35: 4 | L35: 4 | M35: 8 | O35: 20
A36: =ISBLANK(B36)+ISBLANK(C36)+ISBLANK(D36)+ISBLANK(E36)+ISBLANK(F36)+ISBLANK(G36) -> 0 | B36: Buff | C36: Duty's Ward | D36: Move to punish those who threaten your selected ally | E36: This buff links you and one ally (within 60ft on activation) and lasts 24 hours or until one recipient opts to dismiss it as a full action. You are aware of when the linked ally is threatened or hurt. You can sense the rough direction the linked ally is in. Enemies taking actions that target the ally but not you provoke attacks of opportunity. Such a triggering action also grants 10ft of movement if that would allow you to move to threaten the triggering enemy. | F36: 30 | G36: 9W,(12) | O36: 30
A37: =ISBLANK(B37)+ISBLANK(C37)+ISBLANK(D37)+ISBLANK(E37)+ISBLANK(F37)+ISBLANK(G37) -> 0 | B37: Buff | C37: Earthward | D37: Generates temp HP and 3 lightning resist | E37: Body Buff. Every minute and when you activate this ability you generate 2 temporary hp up to half your maximum temp hp. You also gain 6 lightning res. _________________ Temporary HP accrues at the start of each round instead of every minute. | F37: 20,30 | G37: 6G,(12) 12G,(24) | O37: 20 | P37: 50
A38: =ISBLANK(B38)+ISBLANK(C38)+ISBLANK(D38)+ISBLANK(E38)+ISBLANK(F38)+ISBLANK(G38) -> 0 | B38: Buff | C38: Elemental Body (Acid) | D38: Acid: acid retal burst | E38: Gain for the duration Resist Acid: 6*RANK Whenever you are struck by a corporeal attack that does at least 1 point of damage all adjacent creatures must soak (armor soak) acid damage equal to (BOD + 3*RANK). You may channel the acid into an area attack centered on you (you are unaffected by this attack) with (BOD/2*5 ft radius). DV = (BOD+3* RANK)(resolve as a spellcast or attack as desired). Doing so ends the benefits of Elemental Body. This is a body buff. Activating this buff is a half action, channeling the acid is a full action. | F38: 15/25/35 | G38: 2(B|G),(9) 4(B|G),(18) 6(B|G),(27) | H38: 0 | I38: 0 | J38: 6 | K38: 0 | L38: 0 | M38: 6 | O38: 15 | P38: 40 | Q38: 75
A39: =ISBLANK(B39)+ISBLANK(C39)+ISBLANK(D39)+ISBLANK(E39)+ISBLANK(F39)+ISBLANK(G39) -> 0 | B39: Buff | C39: Elemental Body (Air) | D39: Flight, increased movement speed, deflection, immunity to gases/inhaled poisons, wind blast discharge | E39: You gain the ability to (glide, fly as per flight N, fly as per flight NN), your movement speed increases by 10*RANK, you gain +RANK dice vs. ranged attacks, immunity to gases and inhaled poisons, treat wind based vision penalties as RANK steps lower. As a full action you may discharge this buff to produce a (BOD/2)*5ft cone of rushing air, rolling weapon skill or spellcasting vs. all targets in the cone (eDV = BOD + 3*rank). Targets Resist with Physical Resist and soak with Physical soak. Targets are pushed (unsoaked eDV)/2 *5ft directly away from you. | F39: 15/25/35 | G39: 2(W|U),(9) 4(W|U),(18) 6(W|U),(27) | O39: 15 | P39: 40 | Q39: 75
A40: =ISBLANK(B40)+ISBLANK(C40)+ISBLANK(D40)+ISBLANK(E40)+ISBLANK(F40)+ISBLANK(G40) -> 0 | B40: Buff | C40: Elemental Body (Cold) | D40: Cold: chilling presence | E40: Gain for the duration Resist Cold: 6*RANK Creatures that start their turn adjacent lose RANK initiative as if suffering damage from a cold effect. Resistance to cold mitigates this at a 1:1 ratio. You may channel the chill into an area attack centered on you (you are unaffected by this attack) with (BOD/2*5 ft radius). DV = (BOD+ 3*RANK)(resolve as a spellcast or attack as desired). Doing so ends the benefits of Elemental Body. This is a body buff. Activating this buff is a half action, channeling the cold is a full action. | F40: 15/25/35 | G40: 2U,(9) per | H40: 0 | I40: 6 | J40: 0 | K40: 0 | L40: 0 | M40: 6 | O40: 15 | P40: 40 | Q40: 75
...

Sheet NCT
A1: ver 0.53 | C1: Racials | D1: CP | G1: RANK | I1: CP | K1: Dicepool | N1: Current | O1: +Max
A2: BOD | B2: 1 | C2: 1 | D2: =(B2^2+B2-2)*2.5 - 10*C2 -> -10 | E2: B | F2: ATHLETICS | G2: 0 | I2: =IF(G2>0,(G2^2+G2+2)*2.5,0) -> 0 | L2: HP | M2: =16+B2+O2 -> 17 | N2: 9 | O2: 0
A3: AGI | B3: 1 | C3: 1 | D3: =(B3^2+B3-2)*2.5 - 10*C3 -> -10 | E3: A | F3: Strongman | G3: 0 | H3: S | I3: =IF(OR($I$2>0,G3=0),0,(G3^2+G3+2)) -> 0 | J3: =H3 -> S | K3: =OFFSET($B$1, MATCH(H3,$E$2:$E$9,0),0)+IF($G$2>0,$G$2+MIN(CEILING($B$13/2,1),$G$2),G3+IF(G3=0,-1,0)+MIN(CEILING($B$13/2,1),G3)) -> 0 | L3: STAM | M3: =16+B6+O3 -> 17 | N3: 9 | O3: 0
A4: REA | B4: 1 | D4: =(B4^2+B4-2)*2.5 - 10*C4 -> 0 | E4: R | F4: Gymnastics | G4: 0 | H4: A | I4: =IF(OR($I$2>0,G4=0),0,(G4^2+G4+2)) -> 0 | J4: =H4 -> A | K4: =OFFSET($B$1, MATCH(H4,$E$2:$E$9,0),0)+IF($G$2>0,$G$2+MIN(CEILING($B$13/2,1),$G$2),G4+IF(G4=0,-1,0)+MIN(CEILING($B$13/2,1),G4)) -> 0 | L4: DRAIN | M4: =16+OFFSET($B$1, MATCH(H22,$E$2:$E$9,0),0)+O4 -> 17 | N4: 9 | O4: 0
A5: STR | B5: 1 | D5: =(B5^2+B5-2)*2.5 - 10*C5 -> 0 | E5: S | F5: Marathoner | G5: 0 | H5: B | I5: =IF(OR($I$2>0,G5=0),0,(G5^2+G5+2)) -> 0 | J5: =H5 -> B | K5: =OFFSET($B$1, MATCH(H5,$E$2:$E$9,0),0)+IF($G$2>0,$G$2+MIN(CEILING($B$13/2,1),$G$2),G5+IF(G5=0,-1,0)+MIN(CEILING($B$13/2,1),G5)) -> 0 | L5: LUK | M5: =B10 -> 1 | N5: 1
A6: WIL | B6: 1 | D6: =(B6^2+B6-2)*2.5 - 10*C6 -> 0 | E6: W | F6: Traversal | G6: 0 | H6: R | I6: =IF(OR($I$2>0,G6=0),0,(G6^2+G6+2)) -> 0 | J6: =H6 -> R | K6: =OFFSET($B$1, MATCH(H6,$E$2:$E$9,0),0)+IF($G$2>0,$G$2+MIN(CEILING($B$13/2,1),$G$2),G6+IF(G6=0,-1,0)+MIN(CEILING($B$13/2,1),G6)) -> 0 | L6: DV Threshold | M6: =B2 -> 1 | N6: MISC
A7: INT | B7: 1 | D7: =(B7^2+B7-2)*2.5 - 10*C7 -> 0 | E7: I | F7: SURVIVAL | G7: 0 | I7: =IF(G7>0,(G7^2+G7+2)*2.5,0) -> 0 | L7: ARMOR SOAK | M7: =CEILING(((2-1*(L11="Light Armor"))*B2+B8)/2,1)+N7 -> 2
A8: LOG | B8: 1 | D8: =(B8^2+B8-2)*2.5 - 10*C8 -> 0 | E8: L | F8: Navigation | G8: 0 | H8: I | I8: =IF(OR($I$7>0,G8=0),0,(G8^2+G8+2)) -> 0 | J8: =H8 -> I | K8: =OFFSET($B$1, MATCH(H8,$E$2:$E$9,0),0)+IF($G$7>0,$G$7+MIN(CEILING($B$13/2,1),$G$7),G8+IF(G8=0,-1,0)+MIN(CEILING($B$13/2,1),G8)) -> 0 | L8: PHYS SOAK | M8: =CEILING((B3+2*B5)/2,1)+N8 -> 2
A9: CHA | B9: 1 | D9: =(B9^2+B9-2)*2.5 - 10*C9 -> 0 | E9: C | F9: Survival | G9: 0 | H9: W | I9: =IF(OR($I$7>0,G9=0),0,(G9^2+G9+2)) -> 0 | J9: =H9 -> W | K9: =OFFSET($B$1, MATCH(H9,$E$2:$E$9,0),0)+IF($G$7>0,$G$7+MIN(CEILING($B$13/2,1),$G$7),G9+IF(G9=0,-1,0)+MIN(CEILING($B$13/2,1),G9)) -> 0 | L9: MENTAL SOAK | M9: =CEILING((2*B6+B9)/2,1)+N9 -> 2
A10: LUK | B10: 1 | D10: =(B10^2+B10-2)*2.5 - 10*C10 -> 0 | F10: Medicine | G10: 0 | H10: L | I10: =IF(OR($I$7>0,G10=0),0,(G10^2+G10+2)) -> 0 | J10: =H10 -> L | K10: =OFFSET($B$1, MATCH(H10,$E$2:$E$9,0),0)+IF($G$7>0,$G$7+MIN(CEILING($B$13/2,1),$G$7),G10+IF(G10=0,-1,0)+MIN(CEILING($B$13/2,1),G10)) -> 0 | L10: DRAIN SOAK P | M10: =2*B6+N10 -> 2
A11: CAST STAT | B11: LOG | F11: Animal Handling | G11: 0 | H11: I | I11: =IF(OR($I$7>0,G11=0),0,(G11^2+G11+2)) -> 0 | J11: =H11 -> I | K11: =OFFSET($B$1, MATCH(H11,$E$2:$E$9,0),0)+IF($G$7>0,$G$7+MIN(CEILING($B$13/2,1),$G$7),G11+IF(G11=0,-1,0)+MIN(CEILING($B$13/2,1),G11)) -> 0 | L11: Normal Armor | M11: Passive | N11: Active | O11: MISC
F12: INFLUENCE | G12: 0 | I12: =IF(G12>0,(G12^2+G12+2)*2.5,0) -> 0 | L12: Dodge | M12: =B7+B4 -> 2 | N12: =M12+G26+MIN(G26,CEILING(B13/2,1))+O12+(G26*(L11="Light Armor")) -> 2
A13: TRAD | B13: 1 | C13: =(B13^2+7*B13-8)*2.5 -> 0 | F13: Con | G13: 0 | H13: C | I13: =IF(OR($I$12>0,G13=0),0,(G13^2+G13+2)) -> 0 | J13: =H13 -> C | K13: =OFFSET($B$1, MATCH(H13,$E$2:$E$9,0),0)+IF($G$12>0,$G$12+MIN(CEILING($B$13/2,1),$G$12),G13+IF(G13=0,-1,0)+MIN(CEILING($B$13/2,1),G13)) -> 0 | L13: Parry | M13: - | N13: =M12+G24+MIN(CEILING(B13/2,1),G24)+O13+N30 -> 3
A14: W | B14: 0 | F14: Insight | G14: 0 | H14: I | I14: =IF(OR($I$12>0,G14=0),0,(G14^2+G14+2)) -> 0 | J14: =H14 -> I | K14: =OFFSET($B$1, MATCH(H14,$E$2:$E$9,0),0)+IF($G$12>0,$G$12+MIN(CEILING($B$13/2,1),$G$12),G14+IF(G14=0,-1,0)+MIN(CEILING($B$13/2,1),G14)) -> 0 | L14: Block | M14: - | N14: =M12+G24+MIN(CEILING(B13/2,1),G24)+O14+N34 -> 2
A15: U | B15: 0 | F15: Intimidation | G15: 0 | H15: C | I15: =IF(OR($I$12>0,G15=0),0,(G15^2+G15+2)) -> 0 | J15: =H15 -> C | K15: =OFFSET($B$1, MATCH(H15,$E$2:$E$9,0),0)+IF($G$12>0,$G$12+MIN(CEILING($B$13/2,1),$G$12),G15+IF(G15=0,-1,0)+MIN(CEILING($B$13/2,1),G15)) -> 0 | L15: Physical | M15: =B2+B3 -> 2 | N15: =M15+G27+MIN(CEILING(B13/2,1),G27)+O15 -> 2
A16: B | B16: 0 | F16: Negotiation | G16: 0 | H16: C | I16: =IF(OR($I$12>0,G16=0),0,(G16^2+G16+2)) -> 0 | J16: =H16 -> C | K16: =OFFSET($B$1, MATCH(H16,$E$2:$E$9,0),0)+IF($G$12>0,$G$12+MIN(CEILING($B$13/2,1),$G$12),G16+IF(G16=0,-1,0)+MIN(CEILING($B$13/2,1),G16)) -> 0 | L16: Mental | M16: =B6+B9 -> 2 | N16: =M16+G27+MIN(CEILING(B13/2,1),G27)+O16 -> 2
A17: R | B17: 0 | F17: SUBTERFUGE | G17: 0 | I17: =IF(G17>0,(G17^2+G17+2)*2.5,0) -> 0 | M17: 1 | N17: 2 | O17: 3
A18: G | B18: 0 | F18: Disguise | G18: 0 | H18: I | I18: =IF(OR($I$17>0,G18=0),0,(G18^2+G18+2)) -> 0 | J18: =H18 -> I | K18: =OFFSET($B$1, MATCH(H18,$E$2:$E$9,0),0)+IF($G$17>0,$G$17+MIN(CEILING($B$13/2,1),$G$17),G18+IF(G18=0,-1,0)+MIN(CEILING($B$13/2,1),G18)) -> 0 | M18: Melee | N18: Melee | O18: Melee
D19: Know discount | F19: Stealth | G19: 0 | H19: A | I19: =IF(OR($I$17>0,G19=0),0,(G19^2+G19+2)) -> 0 | J19: =H19 -> A | K19: =OFFSET($B$1, MATCH(H19,$E$2:$E$9,0),0)+IF($G$17>0,$G$17+MIN(CEILING($B$13/2,1),$G$17),G19+IF(G19=0,-1,0)+MIN(CEILING($B$13/2,1),G19)) -> 0 | L19: Name
A20: BP Current | B20: =SUM(D2:D10)+SUM(C13:C18)+SUM(I2:I36)+SUM(G41:G125)-MIN(SUM(I28:I36),D20) -> 20 | D20: =(B8+B7)*10 -> 20 | F20: Legerdemain | G20: 0 | H20: A | I20: =IF(OR($I$17>0,G20=0),0,(G20^2+G20+2)) -> 0 | J20: =H20 -> A | K20: =OFFSET($B$1, MATCH(H20,$E$2:$E$9,0),0)+IF($G$17>0,$G$17+MIN(CEILING($B$13/2,1),$G$17),G20+IF(G20=0,-1,0)+MIN(CEILING($B$13/2,1),G20)) -> 0 | L20: Weapon | M20: Light | N20: 1H | O20: 2H
A21: BP Budget | B21: 1620 | F21: Thievery | G21: 0 | H21: A | I21: =IF(OR($I$17>0,G21=0),0,(G21^2+G21+2)) -> 0 | J21: =H21 -> A | K21: =OFFSET($B$1, MATCH(H21,$E$2:$E$9,0),0)+IF($G$17>0,$G$17+MIN(CEILING($B$13/2,1),$G$17),G21+IF(G21=0,-1,0)+MIN(CEILING($B$13/2,1),G21)) -> 0 | L21: Power | M21: 4 | N21: 4 | O21: 6
F22: Spellcasting | G22: 0 | H22: =OFFSET($E$1, MATCH($B$11,$A$2:$A$10,0),0) -> L | I22: =IF(G22>0,(G22^2+G22+2),0) -> 0 | J22: =H22 -> L | K22: =OFFSET($B$1, MATCH(H22,$E$2:$E$9,0),0)+G22+MIN(CEILING($B$13/2,1),G22) -> 1 | L22: Reach | M22: =IF(M$18="Melee", OFFSET($B$24,0,MATCH(M$20,$C$23:$E$23,0))-M$21,0) -> 1 | N22: =IF(N$18="Melee", OFFSET($B$24,0,MATCH(N$20,$C$23:$E$23,0))-N$21,0) -> 2 | O22: =IF(O$18="Melee", OFFSET($B$24,0,MATCH(O$20,$C$23:$E$23,0))-O$21,0) -> 2
C23: Light | D23: 1H | E23: 2H | F23: Perceive Magic | G23: 0 | H23: =OFFSET($E$1, MATCH($B$11,$A$2:$A$10,0),0) -> L | I23: =IF(G23>0,(G23^2+G23+2),0) -> 0 | J23: =H23 -> L | K23: =OFFSET($B$1, MATCH(H23,$E$2:$E$9,0),0)+G23+MIN(CEILING($B$13/2,1),G23) -> 1 | L23: DV | M23: =M$21+$B$5 -> 5 | N23: =N$21+$B$5 -> 5 | O23: =O$21+$B$5 -> 7
C24: 5 | D24: 6 | E24: 8 | F24: (weapon skill) | G24: 0 | H24: A | I24: =IF(G24>0,(G24^2+G24+2),0) -> 0 | J24: =H24 -> A | K24: =OFFSET($B$1, MATCH(H24,$E$2:$E$9,0),0)+G24+MIN(CEILING($B$13/2,1),G24) -> 1 | L24: Dicepool | M24: =$K$24+M$22+IF(AND(M$20="2H",M$25="Buckler"),-2,0) -> 2 | N24: =$K$24+N$22+IF(AND(N$20="2H",N$25="Buckler"),-2,0) -> 3 | O24: =$K$24+O$22+IF(AND(O$20="2H",O$25="Buckler"),-2,0) -> 3
F25: Perception | G25: 0 | H25: I | I25: =IF(G25>0,(G25^2+G25+2),0) -> 0 | J25: =H25 -> I | K25: =OFFSET($B$1, MATCH(H25,$E$2:$E$9,0),0)+G25+MIN(CEILING($B$13/2,1),G25) -> 1 | L25: Shield | M25: None | N25: None | O25: None
F26: Dodge | G26: 0 | H26: N/A | I26: =IF(G26>0,(G26^2+G26+2),0) -> 0 | L26: Shield Bonus | M26: =OFFSET($D$30,MATCH(M$25,$D$26:$D$31,0),0) -> 0 | N26: =OFFSET($D$30,MATCH(N$25,$D$26:$D$31,0),0) -> 0 | O26: =OFFSET($D$30,MATCH(O$25,$D$26:$D$31,0),0) -> 0
C27: None | D27: None | E27: None | F27: Perserverence | G27: 0 | H27: N/A | I27: =IF(G27>0,(G27^2+G27+2),0) -> 0 | M27: Weapon # | N27: 1
C28: Buckler | D28: Buckler | E28: Buckler | F28: Knowledge | G28: 0 | H28: =J28 -> L | I28: =IF(G28>0,(G28^2+G28+2),0)/2 -> 0 | J28: L | K28: =OFFSET($B$1, MATCH(H28,$E$2:$E$9,0),0)+G28+MIN(CEILING($B$13/2,1),G28) -> 1 | M28: Weapon | N28: =OFFSET(L20,0,$N$27) -> Light | O28: X foot reach
C29: Medium | D29: Medium | F29: Knowledge | G29: 0 | H29: =J29 -> L | I29: =IF(G29>0,(G29^2+G29+2),0)/2 -> 0 | J29: L | K29: =OFFSET($B$1, MATCH(H29,$E$2:$E$9,0),0)+G29+MIN(CEILING($B$13/2,1),G29) -> 1 | M29: Power | N29: =OFFSET(L21,0,$N$27)-2*(O33<>"None") -> 4 | O29: =MAX(0,FLOOR(N30/2,1)-1)*5+5 -> 5
C30: Heavy | D30: Heavy | F30: Knowledge | G30: 0 | H30: =J30 -> L | I30: =IF(G30>0,(G30^2+G30+2),0)/2 -> 0 | J30: L | K30: =OFFSET($B$1, MATCH(H30,$E$2:$E$9,0),0)+G30+MIN(CEILING($B$13/2,1),G30) -> 1 | M30: Reach | N30: =OFFSET(L22,0,$N$27)+O31 -> 1 | O30: Reach Bonus
C31: Tower | D31: Tower | F31: Knowledge | G31: 0 | H31: =J31 -> L | I31: =IF(G31>0,(G31^2+G31+2),0)/2 -> 0 | J31: L | K31: =OFFSET($B$1, MATCH(H31,$E$2:$E$9,0),0)+G31+MIN(CEILING($B$13/2,1),G31) -> 1 | M31: DV | N31: =OFFSET(L23,0,$N$27) -> 5 | O31: 0
C32: =OFFSET(B27,0,MATCH($M$20,$C$23:$E$23,0)) -> None | D32: 0 | F32: Knowledge | G32: 0 | H32: =J32 -> L | I32: =IF(G32>0,(G32^2+G32+2),0)/2 -> 0 | J32: L | K32: =OFFSET($B$1, MATCH(H32,$E$2:$E$9,0),0)+G32+MIN(CEILING($B$13/2,1),G32) -> 1 | M32: Dicepool | N32: =OFFSET(L24,0,$N$27) -> 2 | O32: ELEMENT
C33: =OFFSET(B28,0,MATCH($M$20,$C$23:$E$23,0)) -> Buckler | D33: 1 | F33: Knowledge | G33: 0 | H33: =J33 -> L | I33: =IF(G33>0,(G33^2+G33+2),0)/2 -> 0 | J33: L | K33: =OFFSET($B$1, MATCH(H33,$E$2:$E$9,0),0)+G33+MIN(CEILING($B$13/2,1),G33) -> 1 | M33: Shield | N33: =OFFSET(L25,0,$N$27) -> None | O33: None
C34: =OFFSET(B29,0,MATCH($M$20,$C$23:$E$23,0)) -> Medium | D34: 4 | F34: Knowledge | G34: 0 | H34: =J34 -> L | I34: =IF(G34>0,(G34^2+G34+2),0)/2 -> 0 | J34: L | K34: =OFFSET($B$1, MATCH(H34,$E$2:$E$9,0),0)+G34+MIN(CEILING($B$13/2,1),G34) -> 1 | M34: Shield Bonus | N34: =OFFSET(L26,0,$N$27) -> 0
C35: =OFFSET(B30,0,MATCH($M$20,$C$23:$E$23,0)) -> Heavy | D35: 5 | F35: Knowledge | G35: 0 | H35: =J35 -> L | I35: =IF(G35>0,(G35^2+G35+2),0)/2 -> 0 | J35: L | K35: =OFFSET($B$1, MATCH(H35,$E$2:$E$9,0),0)+G35+MIN(CEILING($B$13/2,1),G35) -> 1
C36: =OFFSET(B31,0,MATCH($M$20,$C$23:$E$23,0)) -> Tower | D36: 7 | F36: Knowledge | G36: 0 | H36: =J36 -> L | I36: =IF(G36>0,(G36^2+G36+2),0)/2 -> 0 | J36: L | K36: =OFFSET($B$1, MATCH(H36,$E$2:$E$9,0),0)+G36+MIN(CEILING($B$13/2,1),G36) -> 1
B39: Abilities
A40: Rank | B40: Name | G40: Cost | J40: Affinity
A41: 1 | B41: Break Resolve | G41: =IFERROR(OFFSET(Abilities!$N$1,MATCH(B41,Abilities!C:C,0)-1,A41),0) -> 40 | J41: =OFFSET(Abilities!$N$1,MATCH(B41,Abilities!C:C,0)-1,-7) -> ??,(27) | K41: =OFFSET(Abilities!$N$1,MATCH(B41,Abilities!C:C,0)-1,-12) -> Maneuver | L41: =OFFSET(Abilities!$N$1,MATCH(B41,Abilities!C:C,0)-1,-9) -> (5) When you are the only target of an enemy's action. Make an Intimidation attempt against the enemy. If this puts the enemy to 3 or more fear stacks negate the enemy's action.
A42: 1 | B42: Ability Name | G42: =IFERROR(OFFSET(Abilities!$N$1,MATCH(B42,Abilities!C:C,0)-1,A42),0) -> R1 | J42: =OFFSET(Abilities!$N$1,MATCH(B42,Abilities!C:C,0)-1,-7) -> Affinity req | K42: =OFFSET(Abilities!$N$1,MATCH(B42,Abilities!C:C,0)-1,-12) -> Category | L42: =OFFSET(Abilities!$N$1,MATCH(B42,Abilities!C:C,0)-1,-9) -> Rules Text
...

Sheet Iobia
C1: Racials | D1: CP | G1: RANK | I1: CP | K1: Dicepool | N1: Current | O1: +Max | Q1: To cure being starblinded - flower from the tallest mountain that has seen every sunrise of the year Sunmage has heard about a valley that has not seen rain, cloudless valley. Infer, giant beast nesting grounds (Kaiju) Druidess Lands - druidess, was helped over demon and dumb idiot dude. Iobia has crafted a picture good enough for a sovineirg War Graveyard - Magic Gophers, made fake lord of bones to harrange travelers, shoot fireballs. Fortress westward, skeletons all headless Ziggurat picture - sickness when traveling, boggy area. Indigenous populations. Big giant forest monsters. Ancient Undead City- dust devils, blue chasing green Icey North - ice worms, yetis, dire wolves Kaiju Turtle - Gexians are harvesting his bone marrow, ask Ferrofist for ship diagrams, engine room blow ups, maybe he want to help? Smith murder - coated in molten - Ferrofist - Smith was gexian. What is gexias larger puzzle piece? (gexian outposts could be friendly) Flying ship - Find someone that can inform us better about using power sources Jalguez Tablet - Find someone that may know more about duplicating tablet pieces (find a sage/expert at a college devoted to study) - when more tablets are near (or meteor) they amplify/lash out, also when stored they build up energy. lash outs turn surrounding stuff tentacle Shimmering Reach MAY be finite Merchant Sons - lost merchant fleet carrying fat loot, either blown into Gexia or into the Reach Meteor Quest - Ice cave, meteor was taken already. Big curved 2 handed sword with shark teeth on the hilt, 3 adventurers (one tall one, one with the sword, one using magic)
A2: BOD | B2: 7 | C2: 1 | D2: =(B2^2+B2-2)*2.5 - 10*C2 -> 125 | E2: B | F2: ATHLETICS | G2: 1 | I2: =IF(G2>0,(G2^2+G2+2)*2.5,0) -> 10 | L2: HP | M2: =16+B2+O2 -> 23 | N2: 21 | O2: 0
A3: AGI | B3: 2 | C3: 1 | D3: =(B3^2+B3-2)*2.5 - 10*C3 -> 0 | E3: A | F3: Strongman | G3: 0 | H3: S | I3: =IF(OR($I$2>0,G3=0),0,(G3^2+G3+2)) -> 0 | J3: =H3 -> S | K3: =OFFSET($B$1, MATCH(H3,$E$2:$E$9,0),0)+IF($G$2>0,$G$2+MIN(CEILING($B$13/2,1),$G$2),G3+IF(G3=0,-1,0)+MIN(CEILING($B$13/2,1),G3)) -> 4 | L3: STAM | M3: =16+B6+O3 -> 24 | N3: 18 | O3: 0
A4: REA | B4: 5 | D4: =(B4^2+B4-2)*2.5 - 10*C4 -> 70 | E4: R | F4: Gymnastics | G4: 0 | H4: A | I4: =IF(OR($I$2>0,G4=0),0,(G4^2+G4+2)) -> 0 | J4: =H4 -> A | K4: =OFFSET($B$1, MATCH(H4,$E$2:$E$9,0),0)+IF($G$2>0,$G$2+MIN(CEILING($B$13/2,1),$G$2),G4+IF(G4=0,-1,0)+MIN(CEILING($B$13/2,1),G4)) -> 4 | L4: DRAIN | M4: =16+OFFSET($B$1, MATCH(H22,$E$2:$E$9,0),0)+O4 -> 25 | N4: 21 | O4: 0
A5: STR | B5: 2 | D5: =(B5^2+B5-2)*2.5 - 10*C5 -> 10 | E5: S | F5: Marathoner | G5: 0 | H5: B | I5: =IF(OR($I$2>0,G5=0),0,(G5^2+G5+2)) -> 0 | J5: =H5 -> B | K5: =OFFSET($B$1, MATCH(H5,$E$2:$E$9,0),0)+IF($G$2>0,$G$2+MIN(CEILING($B$13/2,1),$G$2),G5+IF(G5=0,-1,0)+MIN(CEILING($B$13/2,1),G5)) -> 9 | L5: LUK | M5: =B10 -> 5 | N5: 4
A6: WIL | B6: 8 | D6: =(B6^2+B6-2)*2.5 - 10*C6 -> 175 | E6: W | F6: Traversal | G6: 0 | H6: R | I6: =IF(OR($I$2>0,G6=0),0,(G6^2+G6+2)) -> 0 | J6: =H6 -> R | K6: =OFFSET($B$1, MATCH(H6,$E$2:$E$9,0),0)+IF($G$2>0,$G$2+MIN(CEILING($B$13/2,1),$G$2),G6+IF(G6=0,-1,0)+MIN(CEILING($B$13/2,1),G6)) -> 7 | L6: DV Threshold | M6: =B2 -> 7 | N6: MISC
A7: INT | B7: 9 | D7: =(B7^2+B7-2)*2.5 - 10*C7 -> 220 | E7: I | F7: SURVIVAL | G7: 0 | I7: =IF(G7>0,(G7^2+G7+2)*2.5,0) -> 0 | L7: ARMOR SOAK | M7: =CEILING(((2-1*(L11="Light Armor"))*B2+B8)/2,1)+N7 -> 9
A8: LOG | B8: 3 | D8: =(B8^2+B8-2)*2.5 - 10*C8 -> 25 | E8: L | F8: Navigation | G8: 1 | H8: I | I8: =IF(OR($I$7>0,G8=0),0,(G8^2+G8+2)) -> 4 | J8: =H8 -> I | K8: =OFFSET($B$1, MATCH(H8,$E$2:$E$9,0),0)+IF($G$7>0,$G$7+MIN(CEILING($B$13/2,1),$G$7),G8+IF(G8=0,-1,0)+MIN(CEILING($B$13/2,1),G8)) -> 11 | L8: PHYS SOAK | M8: =CEILING((B3+2*B5)/2,1)+N8 -> 3
A9: CHA | B9: 2 | D9: =(B9^2+B9-2)*2.5 - 10*C9 -> 10 | E9: C | F9: Survival | G9: 0 | H9: W | I9: =IF(OR($I$7>0,G9=0),0,(G9^2+G9+2)) -> 0 | J9: =H9 -> W | K9: =OFFSET($B$1, MATCH(H9,$E$2:$E$9,0),0)+IF($G$7>0,$G$7+MIN(CEILING($B$13/2,1),$G$7),G9+IF(G9=0,-1,0)+MIN(CEILING($B$13/2,1),G9)) -> 7 | L9: MENTAL SOAK | M9: =CEILING((2*B6+B9)/2,1)+N9 -> 9
A10: LUK | B10: 5 | D10: =(B10^2+B10-2)*2.5 - 10*C10 -> 70 | F10: Medicine | G10: 1 | H10: L | I10: =IF(OR($I$7>0,G10=0),0,(G10^2+G10+2)) -> 4 | J10: =H10 -> L | K10: =OFFSET($B$1, MATCH(H10,$E$2:$E$9,0),0)+IF($G$7>0,$G$7+MIN(CEILING($B$13/2,1),$G$7),G10+IF(G10=0,-1,0)+MIN(CEILING($B$13/2,1),G10)) -> 5 | L10: DRAIN SOAK P | M10: =2*B6+N10 -> 16
A11: CAST STAT | B11: INT | F11: Animal Handling | G11: 0 | H11: I | I11: =IF(OR($I$7>0,G11=0),0,(G11^2+G11+2)) -> 0 | J11: =H11 -> I | K11: =OFFSET($B$1, MATCH(H11,$E$2:$E$9,0),0)+IF($G$7>0,$G$7+MIN(CEILING($B$13/2,1),$G$7),G11+IF(G11=0,-1,0)+MIN(CEILING($B$13/2,1),G11)) -> 8 | L11: Normal Armor | M11: Passive | N11: Active | O11: MISC | Q11: Sketches Large giant albino finned sea monster, 4 part mouth, dives deep and then rises, using its maw to vortex massive amounts of water consuming the flesh inside Herald of fire and ash demon skull Charcoal relief of tablet piece Souviner picture of Daemon, Northerner, and Druid with the well of souls Oil painting of Petradonis - rat city, huge towering white walls surrounded by field of demons with a shimmering wall all around Bracelet of Teeth Death Mage Tooth Ash Demon Tooth Dire Wolf Tooth Statue of petrified tentacle rat (both the tablet relief made it turn green with some tentacles and dark damage amplified it) then silas petrified it
F12: INFLUENCE | G12: 0 | I12: =IF(G12>0,(G12^2+G12+2)*2.5,0) -> 0 | L12: Dodge | M12: =B7+B4 -> 14 | N12: =M12+G26+MIN(G26,CEILING(B13/2,1))+O12+(G26*(L11="Light Armor")) -> 26
A13: TRAD | B13: 10 | C13: =(B13^2+7*B13-8)*2.5 -> 405 | F13: Con | G13: 2 | H13: C | I13: =IF(OR($I$12>0,G13=0),0,(G13^2+G13+2)) -> 8 | J13: =H13 -> C | K13: =OFFSET($B$1, MATCH(H13,$E$2:$E$9,0),0)+IF($G$12>0,$G$12+MIN(CEILING($B$13/2,1),$G$12),G13+IF(G13=0,-1,0)+MIN(CEILING($B$13/2,1),G13)) -> 6 | L13: Parry | M13: - | N13: =M12+G24+MIN(CEILING(B13/2,1),G24)+O13+N30 -> 14
A14: W | B14: 0 | F14: Insight | G14: 0 | H14: I | I14: =IF(OR($I$12>0,G14=0),0,(G14^2+G14+2)) -> 0 | J14: =H14 -> I | K14: =OFFSET($B$1, MATCH(H14,$E$2:$E$9,0),0)+IF($G$12>0,$G$12+MIN(CEILING($B$13/2,1),$G$12),G14+IF(G14=0,-1,0)+MIN(CEILING($B$13/2,1),G14)) -> 8 | L14: Block | M14: - | N14: =M12+G24+MIN(CEILING(B13/2,1),G24)+O14+N34 -> 14
A15: U | B15: 19 | F15: Intimidation | G15: 0 | H15: C | I15: =IF(OR($I$12>0,G15=0),0,(G15^2+G15+2)) -> 0 | J15: =H15 -> C | K15: =OFFSET($B$1, MATCH(H15,$E$2:$E$9,0),0)+IF($G$12>0,$G$12+MIN(CEILING($B$13/2,1),$G$12),G15+IF(G15=0,-1,0)+MIN(CEILING($B$13/2,1),G15)) -> 1 | L15: Physical | M15: =B2+B3 -> 9 | N15: =M15+G27+MIN(CEILING(B13/2,1),G27)+O15 -> 19
A16: B | B16: 0 | F16: Negotiation | G16: 0 | H16: C | I16: =IF(OR($I$12>0,G16=0),0,(G16^2+G16+2)) -> 0 | J16: =H16 -> C | K16: =OFFSET($B$1, MATCH(H16,$E$2:$E$9,0),0)+IF($G$12>0,$G$12+MIN(CEILING($B$13/2,1),$G$12),G16+IF(G16=0,-1,0)+MIN(CEILING($B$13/2,1),G16)) -> 1 | L16: Mental | M16: =B6+B9 -> 10 | N16: =M16+G27+MIN(CEILING(B13/2,1),G27)+O16 -> 20
A17: R | B17: 11 | F17: SUBTERFUGE | G17: 0 | I17: =IF(G17>0,(G17^2+G17+2)*2.5,0) -> 0 | M17: 1 | N17: 2 | O17: 3
A18: G | B18: 0 | F18: Disguise | G18: 0 | H18: I | I18: =IF(OR($I$17>0,G18=0),0,(G18^2+G18+2)) -> 0 | J18: =H18 -> I | K18: =OFFSET($B$1, MATCH(H18,$E$2:$E$9,0),0)+IF($G$17>0,$G$17+MIN(CEILING($B$13/2,1),$G$17),G18+IF(G18=0,-1,0)+MIN(CEILING($B$13/2,1),G18)) -> 8 | M18: Melee | N18: Melee | O18: Melee
D19: Know discount | F19: Stealth | G19: 1 | H19: A | I19: =IF(OR($I$17>0,G19=0),0,(G19^2+G19+2)) -> 4 | J19: =H19 -> A | K19: =OFFSET($B$1, MATCH(H19,$E$2:$E$9,0),0)+IF($G$17>0,$G$17+MIN(CEILING($B$13/2,1),$G$17),G19+IF(G19=0,-1,0)+MIN(CEILING($B$13/2,1),G19)) -> 4 | L19: Name
A20: BP Current | B20: =SUM(D2:D10)+SUM(C13:C18)+SUM(I2:I44)+SUM(G37:G121)-MIN(SUM(I34:I44),D20) -> 2020 | D20: =(B8+B7)*10 -> 120 | F20: Legerdemain | G20: 3 | H20: A | I20: =IF(OR($I$17>0,G20=0),0,(G20^2+G20+2)) -> 14 | J20: =H20 -> A | K20: =OFFSET($B$1, MATCH(H20,$E$2:$E$9,0),0)+IF($G$17>0,$G$17+MIN(CEILING($B$13/2,1),$G$17),G20+IF(G20=0,-1,0)+MIN(CEILING($B$13/2,1),G20)) -> 8 | L20: Weapon | M20: Light | N20: 1H | O20: 2H
A21: BP Budget | B21: 2040 | F21: Thievery | G21: 0 | H21: A | I21: =IF(OR($I$17>0,G21=0),0,(G21^2+G21+2)) -> 0 | J21: =H21 -> A | K21: =OFFSET($B$1, MATCH(H21,$E$2:$E$9,0),0)+IF($G$17>0,$G$17+MIN(CEILING($B$13/2,1),$G$17),G21+IF(G21=0,-1,0)+MIN(CEILING($B$13/2,1),G21)) -> 1 | L21: Power | M21: 6 | N21: 8 | O21: 10 | Q21: Character Appearance Captain's hat, large and ink black with gold trim. A weather proof jacket in much the same style. An ash grey dress, flames seem to smolder as the dress flows, hints of deep reds and oranges. Her snake body, scaly from the waste down, with spines protruding. A snake-like torso with fish scales instead of skin, blue hued sandy colored on the front and darker on the back Centering Math Max Center: 28 Drain Soak (7 hits take 4) Max Overload: 11
F22: Spellcasting | G22: 9 | H22: =OFFSET($E$1, MATCH($B$11,$A$2:$A$10,0),0) -> I | I22: =IF(G22>0,(G22^2+G22+2),0) -> 92 | J22: =H22 -> I | K22: =OFFSET($B$1, MATCH(H22,$E$2:$E$9,0),0)+G22+MIN(CEILING($B$13/2,1),G22) -> 23 | L22: Reach | M22: =IF(M$18="Melee", OFFSET($B$24,0,MATCH(M$20,$C$23:$E$23,0))-M$21,0) -> -1 | N22: =IF(N$18="Melee", OFFSET($B$24,0,MATCH(N$20,$C$23:$E$23,0))-N$21,0) -> -2 | O22: =IF(O$18="Melee", OFFSET($B$24,0,MATCH(O$20,$C$23:$E$23,0))-O$21,0) -> -2
C23: Light | D23: 1H | E23: 2H | F23: Perceive Magic | G23: 5 | H23: =OFFSET($E$1, MATCH($B$11,$A$2:$A$10,0),0) -> I | I23: =IF(G23>0,(G23^2+G23+2),0) -> 32 | J23: =H23 -> I | K23: =OFFSET($B$1, MATCH(H23,$E$2:$E$9,0),0)+G23+MIN(CEILING($B$13/2,1),G23) -> 19 | L23: DV | M23: =M$21+$B$5 -> 8 | N23: =N$21+$B$5 -> 10 | O23: =O$21+$B$5 -> 12
C24: 5 | D24: 6 | E24: 8 | F24: (weapon skill) | G24: 0 | H24: A | I24: =IF(G24>0,(G24^2+G24+2),0) -> 0 | J24: =H24 -> A | K24: =OFFSET($B$1, MATCH(H24,$E$2:$E$9,0),0)+G24+MIN(CEILING($B$13/2,1),G24) -> 2 | L24: Dicepool | M24: =$K$24+M$22+IF(AND(M$20="2H",M$25="Buckler"),-2,0) -> 1 | N24: =$K$24+N$22+IF(AND(N$20="2H",N$25="Buckler"),-2,0) -> 0 | O24: =$K$24+O$22+IF(AND(O$20="2H",O$25="Buckler"),-2,0) -> 0
F25: Perception | G25: 5 | H25: I | I25: =IF(G25>0,(G25^2+G25+2),0) -> 32 | J25: =H25 -> I | K25: =OFFSET($B$1, MATCH(H25,$E$2:$E$9,0),0)+G25+MIN(CEILING($B$13/2,1),G25) -> 19 | L25: Shield | M25: None | N25: None | O25: None
F26: Dodge | G26: 7 | H26: N/A | I26: =IF(G26>0,(G26^2+G26+2),0) -> 58 | L26: Shield Bonus | M26: =OFFSET($D$30,MATCH(M$25,$D$26:$D$31,0),0) -> 0 | N26: =OFFSET($D$30,MATCH(N$25,$D$26:$D$31,0),0) -> 0 | O26: =OFFSET($D$30,MATCH(O$25,$D$26:$D$31,0),0) -> 0
C27: None | D27: None | E27: None | F27: Perserverence | G27: 5 | H27: N/A | I27: =IF(G27>0,(G27^2+G27+2),0) -> 32 | M27: Weapon # | N27: 1
B28: Magical Theory | C28: Buckler | D28: Buckler | E28: Buckler | F28: Knowledge | G28: 0 | H28: =J28 -> L | I28: =IF(G28>0,(G28^2+G28+2),0)/2 -> 0 | J28: L | K28: =OFFSET($B$1, MATCH(H28,$E$2:$E$9,0),0)+G28+MIN(CEILING($B$13/2,1),G28) -> 3 | M28: Weapon | N28: =OFFSET(L20,0,$N$27) -> Light | O28: X foot reach
B29: Writing | C29: Medium | D29: Medium | F29: Knowledge | G29: 0 | H29: =J29 -> L | I29: =IF(G29>0,(G29^2+G29+2),0)/2 -> 0 | J29: L | K29: =OFFSET($B$1, MATCH(H29,$E$2:$E$9,0),0)+G29+MIN(CEILING($B$13/2,1),G29) -> 3 | M29: Power | N29: =OFFSET(L21,0,$N$27)-2*(O33<>"None") -> 6 | O29: =MAX(0,FLOOR(N30/2,1)-1)*5+5 -> 5
B30: Art | C30: Heavy | D30: Heavy | F30: Knowledge | G30: 0 | H30: =J30 -> L | I30: =IF(G30>0,(G30^2+G30+2),0)/2 -> 0 | J30: L | K30: =OFFSET($B$1, MATCH(H30,$E$2:$E$9,0),0)+G30+MIN(CEILING($B$13/2,1),G30) -> 3 | M30: Reach | N30: =OFFSET(L22,0,$N$27)+O31 -> 0 | O30: Reach Bonus
B31: Astronomy | C31: Tower | D31: Tower | F31: Knowledge | G31: 0 | H31: =J31 -> L | I31: =IF(G31>0,(G31^2+G31+2),0)/2 -> 0 | J31: L | K31: =OFFSET($B$1, MATCH(H31,$E$2:$E$9,0),0)+G31+MIN(CEILING($B$13/2,1),G31) -> 3 | M31: DV | N31: =OFFSET(L23,0,$N$27) -> 8 | O31: 1 | Q31: Vial from Genie room 3 alchemical phoenix fire vials 5 reams of mica tablets Coat of always clean Lich's Sceptre (powering Iobia's planetarium) Ring of Illumination (small amount of light) Shadowy Quill (shadowless cursed) Cloak of Ele Res (resists last hit element, res 3) 6 bottles of phoenix blood 2 feathers Water Cube => absorbs water, keeps objects it touches moist, can launch water (water shield, water bubble) Backpack of Holding full of someone's bag of holding of loot
C32: =OFFSET(B27,0,MATCH($M$20,$C$23:$E$23,0)) -> None | D32: 0 | F32: Knowledge | G32: 0 | H32: =J32 -> I | I32: =IF(G32>0,(G32^2+G32+2),0)/2 -> 0 | J32: I | K32: =OFFSET($B$1, MATCH(H32,$E$2:$E$9,0),0)+G32+MIN(CEILING($B$13/2,1),G32) -> 9 | M32: Dicepool | N32: =OFFSET(L24,0,$N$27) -> 1 | O32: ELEMENT
C33: =OFFSET(B28,0,MATCH($M$20,$C$23:$E$23,0)) -> Buckler | D33: 1 | F33: Knowledge | G33: 0 | H33: =J33 -> I | I33: =IF(G33>0,(G33^2+G33+2),0)/2 -> 0 | J33: I | K33: =OFFSET($B$1, MATCH(H33,$E$2:$E$9,0),0)+G33+MIN(CEILING($B$13/2,1),G33) -> 9 | M33: Shield | N33: =OFFSET(L25,0,$N$27) -> None | O33: None
C34: =OFFSET(B29,0,MATCH($M$20,$C$23:$E$23,0)) -> Medium | D34: 4 | F34: Knowledge | G34: 0 | H34: =J34 -> I | I34: =IF(G34>0,(G34^2+G34+2),0)/2 -> 0 | J34: I | K34: =OFFSET($B$1, MATCH(H34,$E$2:$E$9,0),0)+G34+MIN(CEILING($B$13/2,1),G34) -> 9 | M34: Shield Bonus | N34: =OFFSET(L26,0,$N$27) -> 0
C35: =OFFSET(B30,0,MATCH($M$20,$C$23:$E$23,0)) -> Heavy | D35: 5 | F35: Knowledge | G35: 0 | H35: =J35 -> I | I35: =IF(G35>0,(G35^2+G35+2),0)/2 -> 0 | J35: I | K35: =OFFSET($B$1, MATCH(H35,$E$2:$E$9,0),0)+G35+MIN(CEILING($B$13/2,1),G35) -> 9
C36: =OFFSET(B31,0,MATCH($M$20,$C$23:$E$23,0)) -> Tower | D36: 7 | F36: Knowledge | G36: 0 | H36: =J36 -> I | I36: =IF(G36>0,(G36^2+G36+2),0)/2 -> 0 | J36: I | K36: =OFFSET($B$1, MATCH(H36,$E$2:$E$9,0),0)+G36+MIN(CEILING($B$13/2,1),G36) -> 9
B39: Abilities
A40: Rank | B40: Name | G40: Cost | J40: Affinity
A41: 1 | B41: Photographic memory | G41: =IFERROR(OFFSET(Abilities!$N$1,MATCH(B41,Abilities!C:C,0)-1,A41),0) -> 3 | J41: =OFFSET(Abilities!$N$1,MATCH(B41,Abilities!C:C,0)-1,-7) -> 3U,(6) | K41: =OFFSET(Abilities!$N$1,MATCH(B41,Abilities!C:C,0)-1,-12) -> Passive | L41: =OFFSET(Abilities!$N$1,MATCH(B41,Abilities!C:C,0)-1,-9) -> Gain 2 dice on knowledge checks to remember something. You may recall additional relevant details by prompting the GM for a clearer picture of a memory, subject to GM discretion. Rolling memory is now faster (typically a Extra action).
A42: 1 | B42: Mcguiver | G42: =IFERROR(OFFSET(Abilities!$N$1,MATCH(B42,Abilities!C:C,0)-1,A42),0) -> 5 | J42: =OFFSET(Abilities!$N$1,MATCH(B42,Abilities!C:C,0)-1,-7) -> 7(U|R),(9) | K42: =OFFSET(Abilities!$N$1,MATCH(B42,Abilities!C:C,0)-1,-12) -> Manuever | L42: =OFFSET(Abilities!$N$1,MATCH(B42,Abilities!C:C,0)-1,-9) -> You may attempt to fix or break mechanical and/or magical devices such as locks or crystal balls. Who knows what will happen! (needs actual rules ffs)
...
